2022-05-09 10:12:31.585807 >>> {command: get_health}
2022-05-09 10:12:31.762268 <<< {isError: false, response: {status: ok}, type: _extensionType, method: ext.flutter.driver}
2022-05-09 10:12:31.775056 >>> {command: request_data, timeout: 1200000}
2022-05-09 10:12:43.131306 <<< {isError: false, response: {message: {"result":"false","failureDetails":["{\"methodName\":\"Complete test\",\"details\":\"══╡ EXCEPTION CAUGHT BY FLUTTER TEST FRAMEWORK ╞═════════════════\\nThe following TestFailure was thrown running a test:\\nExpected: <false>\\n  Actual: <true>\\n\\nWhen the exception was thrown, this was the stack:\\n#4      main.<anonymous closure> (file:///C:/Users/perfil/Downloads/f_local_database_shared_prefs_template-main/f_local_database_shared_prefs_template-main/integration_test/app_test.dart:79:5)\\n<asynchronous suspension>\\n#5      testWidgets.<anonymous closure>.<anonymous closure> (package:flutter_test/src/widget_tester.dart:170:15)\\n<asynchronous suspension>\\n#6      TestWidgetsFlutterBinding._runTestBody (package:flutter_test/src/binding.dart:806:5)\\n<asynchronous suspension>\\n\\nThis was caught by the test expectation on the following line:\\n  file:///C:/Users/perfil/Downloads/f_local_database_shared_prefs_template-main/f_local_database_shared_prefs_template-main/integration_test/app_test.dart line 79\\nThe test description was:\\n  Complete test\\n═════════════════════════════════════════════════════════════════\\n\"}"]}}, type: _extensionType, method: ext.flutter.driver}
